#VRML_SIM R2020b utf8
WorldInfo {
  coordinateSystem "NUE"
}
Viewpoint {
  orientation -0.952514310033928 -0.20768351536623278 -0.2226747552501501 0.3873059645162665
  position 2.106081690414571 5.352908282999333 14.43991556930224
}
TexturedBackground {
}
TexturedBackgroundLight {
}
RectangleArena {
  floorSize 10 10
}
DEF supervisor Robot {
  translation 0.1 0 0.1
  children [
    DEF emitter1 Emitter {
      name "emitter1"
      channel 1
    }
    DEF emitter2 Emitter {
      name "emitter2"
      channel 2
    }
    DEF receiver1 Receiver {
      name "receiver1"
      channel 1
    }
    DEF receiver2 Receiver {
      name "receiver2"
      channel 2
    }
  ]
  name "supervisor"
  controller "SupervisorController"
  supervisor TRUE
}
DEF robot1 Robot {
  translation -0.620001 0.477233 -0.488049
  rotation 0.004773081037872284 0.004773081037872284 0.9999772174378834 -1.5708153071795863
  children [
    DEF connector1 Connector {
      translation 0 -0.42 0
      rotation 0 0 1 3.14159
    }
    DEF connector2 Connector {
      translation 0.365 0.42 0
      rotation 0 0 1 -1.5708
      name "connector2"
    }
    DEF connector3 Connector {
      translation -0.365 0.42 0
      rotation 0 0 1 1.5708
      name "connector3"
    }
    Receiver {
      channel 1
    }
    Emitter {
      channel 1
    }
    DEF gyro Gyro {
    }
    DEF accelerometer Accelerometer {
    }
    DEF leg1 Shape {
      appearance PBRAppearance {
        baseColor 0.45098 0.823529 0.0862745
        metalness 0
      }
      geometry DEF boxA Box {
        size 0.73 0.84 0.3
      }
    }
    HingeJoint {
      jointParameters HingeJointParameters {
        position 1.2
        anchor 0 0.42 0
        staticFriction 0.1
      }
      device [
        RotationalMotor {
          name "motor"
        }
      ]
      endPoint Solid {
        translation 0 0.5214601767477713 0.26097094193475073
        rotation 1 0 0 1.2
        children [
          DEF connector4 Connector {
            translation 0 0.434 0
          }
          DEF leg2 Shape {
            appearance PBRAppearance {
              baseColor 0.45098 0.823529 0.0862745
              metalness 0
            }
            geometry DEF boxB Box {
              size 0.73 0.868 0.3
            }
          }
        ]
        boundingObject USE boxB
        physics Physics {
          mass 0.4
        }
      }
    }
  ]
  name "robot1"
  boundingObject USE boxA
  physics Physics {
    mass 0.28
  }
  controller "JointController"
}
DEF robot2 Robot {
  translation 1.42 0.658374 -0.375687
  rotation -0.9999999635219661 -0.0002217919919094639 -0.00015415699437665574 -0.012775307179586193
  children [
    DEF connector1 Connector {
      translation 0 -0.42 0
      rotation 0 0 1 3.14159
    }
    DEF connector2 Connector {
      translation 0.365 0.42 0
      rotation 0 0 1 -1.5708
      name "connector2"
    }
    DEF connector3 Connector {
      translation -0.365 0.42 0
      rotation 0 0 1 1.5708
      name "connector3"
    }
    Receiver {
      channel 2
    }
    Emitter {
      channel 2
    }
    DEF gyro Gyro {
    }
    DEF accelerometer Accelerometer {
    }
    DEF leg1 Shape {
      appearance PBRAppearance {
        baseColor 0.45098 0.823529 0.0862745
        metalness 0
      }
      geometry DEF boxA Box {
        size 0.73 0.84 0.3
      }
    }
    HingeJoint {
      jointParameters HingeJointParameters {
        anchor 0 0.42 0
        staticFriction 0.1
      }
      device [
        RotationalMotor {
          name "motor"
        }
      ]
      endPoint Solid {
        translation 0 0.7 0
        rotation 1 0 0 0
        children [
          DEF connector4 Connector {
            translation 0 0.434 0
          }
          DEF leg2 Shape {
            appearance PBRAppearance {
              baseColor 0.45098 0.823529 0.0862745
              metalness 0
            }
            geometry DEF boxB Box {
              size 0.73 0.868 0.3
            }
          }
        ]
        boundingObject USE boxB
        physics Physics {
          mass 0.4
        }
      }
    }
  ]
  name "robot2"
  boundingObject USE boxA
  physics Physics {
    mass 0.28
  }
  controller "JointController"
}
