#VRML_SIM R2020b utf8
WorldInfo {
  coordinateSystem "NUE"
}
Viewpoint {
  orientation 0.33369764377116184 -0.9100882588391047 -0.24573409137680038 4.675107384167243
  position 2.1400289960192347 1.280762392341355 -0.2972790716728171
}
TexturedBackground {
}
TexturedBackgroundLight {
}
RectangleArena {
  floorSize 10 10
}
DEF supervisor Robot {
  translation 0.1 0 0.1
  children [
    DEF emitter1 Emitter {
      name "emitter1"
      channel 1
    }
    DEF emitter2 Emitter {
      name "emitter2"
      channel 2
    }
    DEF receiver1 Receiver {
      name "receiver1"
      channel 1
    }
    DEF receiver2 Receiver {
      name "receiver2"
      channel 2
    }
  ]
  name "supervisor"
  controller "SupervisorController"
  supervisor TRUE
}
DEF robot1 Robot {
  translation 1.1560580086257478e-15 0.2072469900892587 -0.4854702799015024
  rotation 1 3.703843537917367e-15 -1.668336859148374e-15 -0.009546307247940401
  children [
    Receiver {
      channel 1
    }
    Emitter {
      channel 1
    }
    DEF gyro Gyro {
    }
    DEF accelerometer Accelerometer {
    }
    DEF leg1 Shape {
      appearance PBRAppearance {
        baseColor 0.45098 0.823529 0.0862745
        metalness 0
      }
      geometry DEF boxA Box {
        size 0.1 0.2 0.1
      }
    }
    HingeJoint {
      jointParameters HingeJointParameters {
        position 2.1053312204699637e-08
        anchor 0 -0.11 0
        staticFriction 0.1
      }
      device [
        RotationalMotor {
          name "motor"
        }
      ]
      endPoint Solid {
        translation 2.7755575615628975e-17 -0.16000000252639773 0.1199999989473344
        rotation 1 -1.014367188999379e-16 1.146002151481655e-16 1.5708000210533084
        children [
          DEF leg2 Shape {
            appearance PBRAppearance {
              baseColor 0.45098 0.823529 0.0862745
              metalness 0
            }
            geometry DEF boxB Box {
              size 0.1 0.2 0.1
            }
          }
        ]
        boundingObject USE boxB
        physics Physics {
        }
      }
    }
  ]
  name "robot1"
  boundingObject USE boxA
  physics Physics {
  }
  controller "JointController"
}
DEF robot2 Robot {
  translation 0.82 0.04842632776675006 -0.3834822803833158
  rotation 1 2.349100191610099e-15 2.1951692571151304e-15 -1.5580184614561345
  children [
    Receiver {
      channel 2
    }
    Emitter {
      channel 2
    }
    DEF gyro Gyro {
    }
    DEF accelerometer Accelerometer {
    }
    DEF leg1 Shape {
      appearance PBRAppearance {
        baseColor 0.45098 0.823529 0.0862745
        metalness 0
      }
      geometry DEF boxA Box {
        size 0.1 0.2 0.1
      }
    }
    HingeJoint {
      jointParameters HingeJointParameters {
        position 1.0111426470560416e-06
        anchor 0 -0.11 0
        staticFriction 0.1
      }
      device [
        RotationalMotor {
          name "motor"
        }
      ]
      endPoint Solid {
        translation 2.7755575615628907e-17 -0.16000012133709235 0.11999994944280604
        rotation 1 1.2579108914443577e-16 -1.3125180032876373e-16 1.5708010111426438
        children [
          DEF leg2 Shape {
            appearance PBRAppearance {
              baseColor 0.45098 0.823529 0.0862745
              metalness 0
            }
            geometry DEF boxB Box {
              size 0.1 0.2 0.1
            }
          }
        ]
        boundingObject USE boxB
        physics Physics {
        }
      }
    }
  ]
  name "robot2"
  boundingObject USE boxA
  physics Physics {
  }
  controller "JointController"
}
