#VRML_SIM R2020b utf8
WorldInfo {
  coordinateSystem "NUE"
}
Viewpoint {
  orientation 0.11177170842184327 -0.8205519503995712 -0.5605368693421712 3.3429823710992377
  position 0.16296411332088392 3.1001739020306043 -1.5938415334499396
}
TexturedBackground {
}
TexturedBackgroundLight {
}
RectangleArena {
  floorSize 10 10
}
DEF supervisor Robot {
  translation 0.1 0 0.1
  children [
    DEF emitter1 Emitter {
      name "emitter1"
      channel 1
    }
    DEF emitter2 Emitter {
      name "emitter2"
      channel 2
    }
    DEF receiver1 Receiver {
      name "receiver1"
      channel 1
    }
    DEF receiver2 Receiver {
      name "receiver2"
      channel 2
    }
  ]
  name "supervisor"
  controller "SupervisorController"
  supervisor TRUE
}
DEF robot1 Robot {
  translation 1.1560580086257478e-15 0.2072469900892587 -0.4854702799015024
  rotation 0.004773081037872284 0.004773081037872284 0.9999772174378834 -1.5708153071795863
  children [
    Solid {
      children [
        DEF leg1 Shape {
          appearance PBRAppearance {
            baseColor 0 0 1
            metalness 0
          }
          geometry DEF boxA Box {
            size 0.1 0.2 0.1
          }
        }
      ]
      name "solid(1)"
      boundingObject Box {
        size 0.1 0.2 0.1
      }
      physics Physics {
        density -1
        mass 0.0695
      }
    }
    Receiver {
      channel 1
    }
    Emitter {
      channel 1
    }
    DEF gyro Gyro {
    }
    DEF accelerometer Accelerometer {
      boundingObject Box {
        size 0.1 0.1 0.1
      }
      physics Physics {
        density -1
        mass 0.021
      }
    }
    HingeJoint {
      jointParameters HingeJointParameters {
        position 2.1053312204699637e-08
        anchor 0 -0.11 0
        staticFriction 0.1
      }
      device [
        RotationalMotor {
          name "motor"
          maxVelocity 3.7
          maxTorque 1.1
        }
      ]
      endPoint Solid {
        translation 8.196568423990418e-17 -0.16000000252639784 0.11999999894733754
        rotation 1 1.0089052046011127e-16 2.5452623702702834e-16 1.5708000210533075
        children [
          DEF leg2 Shape {
            appearance PBRAppearance {
              baseColor 0.45098 0.823529 0.0862745
              metalness 0
            }
            geometry DEF boxB Box {
              size 0.1 0.2 0.1
            }
          }
        ]
        boundingObject USE boxB
        physics Physics {
          density -1
          mass 0.0695
        }
      }
    }
  ]
  name "robot1"
  boundingObject DEF boxA Box {
    size 0.1 0.2 0.1
  }
  physics Physics {
  }
  controller "JointController"
}
DEF robot2 Robot {
  translation 0.82 0.238408 -0.38105
  rotation -0.9999999635219661 -0.0002217919919094639 -0.00015415699437665574 -0.012775307179586193
  children [
    Solid {
      children [
        DEF leg1 Shape {
          appearance PBRAppearance {
            baseColor 1 0 0
            metalness 0
          }
          geometry DEF boxA Box {
            size 0.1 0.2 0.1
          }
        }
      ]
      name "solid(1)"
      boundingObject Box {
        size 0.1 0.2 0.1
      }
      physics Physics {
        density -1
        mass 0.0695
      }
    }
    Receiver {
      channel 2
    }
    Emitter {
      channel 2
    }
    DEF gyro Gyro {
    }
    DEF accelerometer Accelerometer {
      boundingObject Box {
        size 0.1 0.1 0.1
      }
      physics Physics {
        density -1
        mass 0.021
      }
    }
    HingeJoint {
      jointParameters HingeJointParameters {
        position 1.0111426470560416e-06
        anchor 0 -0.11 0
        staticFriction 0.1
      }
      device [
        RotationalMotor {
          name "motor"
          maxVelocity 3.7
          maxTorque 1.1
        }
      ]
      endPoint Solid {
        translation 1.3322676295501878e-15 -0.16000012133709235 0.11999994944280606
        rotation 1 1.2576081705240476e-16 -1.3124481752834704e-16 1.5708010111426438
        children [
          DEF leg2 Shape {
            appearance PBRAppearance {
              baseColor 1 0 0
              metalness 0
            }
            geometry DEF boxB Box {
              size 0.1 0.2 0.1
            }
          }
        ]
        boundingObject USE boxB
        physics Physics {
          density -1
          mass 0.0695
        }
      }
    }
  ]
  name "robot2"
  boundingObject USE boxA
  physics Physics {
  }
  controller "JointController"
}
