#VRML_SIM R2020b utf8
WorldInfo {
  coordinateSystem "NUE"
}
Viewpoint {
  orientation 0.10202498954620186 0.9809010205238643 0.16560220241089413 4.752980963857972
  position -19.587048741262386 4.453041333435637 3.3830629933851166
}
TexturedBackground {
}
TexturedBackgroundLight {
}
RectangleArena {
  floorSize 10 10
}
DEF supervisor Robot {
  translation 0.1 0 0.1
  children [
    DEF emitter1 Emitter {
      name "emitter1"
      channel 1
    }
    DEF emitter2 Emitter {
      name "emitter2"
      channel 2
    }
    DEF receiver1 Receiver {
      name "receiver1"
      channel 1
    }
    DEF receiver2 Receiver {
      name "receiver2"
      channel 2
    }
  ]
  name "supervisor"
  controller "SupervisorController"
  supervisor TRUE
}
DEF robot2 Robot {
  translation 1.1396390652851431e-17 0.2093558381998357 2.548086792747208
  rotation 1 2.92178550590197e-16 4.4146871431426116e-17 1.5597329563817681
  children [
    DEF connector1 Connector {
      translation 0 -0.42 0
      rotation 0 0 1 3.14159
      isLocked TRUE
      autoLock TRUE
      distanceTolerance 0.1
      axisTolerance 3.141592653589793
      rotationTolerance 3.14159
      snap FALSE
    }
    DEF connector2 Connector {
      translation 0.365 0.42 0
      rotation 0 0 1 -1.5708
      name "connector2"
    }
    DEF connector3 Connector {
      translation -0.365 0.42 0
      rotation 0 0 1 1.5708
      name "connector3"
    }
    Receiver {
      channel 2
    }
    Emitter {
      channel 2
    }
    DEF gyro Gyro {
    }
    DEF accelerometer Accelerometer {
    }
    DEF leg1 Shape {
      appearance PBRAppearance {
        baseColor 0.45098 0.823529 0.0862745
        metalness 0
      }
      geometry DEF boxA Box {
        size 0.73 0.84 0.3
      }
    }
    HingeJoint {
      jointParameters HingeJointParameters {
        position 0.10538232811854173
        anchor 0 0.42 0
        staticFriction 0.1
      }
      device [
        RotationalMotor {
          name "motor"
        }
      ]
      endPoint Solid {
        translation 0 0.698446677414342 0.029452467416387636
        rotation 1 -1.705372726661084e-15 1.4641866645813596e-17 0.10538232811854173
        children [
          DEF connector4 Connector {
            translation 0 0.434 0
          }
          DEF leg2 Shape {
            appearance PBRAppearance {
              baseColor 0.45098 0.823529 0.0862745
              metalness 0
            }
            geometry DEF boxB Box {
              size 0.73 0.868 0.3
            }
          }
        ]
        boundingObject USE boxB
        physics Physics {
          mass 0.4
        }
        linearVelocity -1.331880254182252e-15 0.19028452999125756 -0.06301687856706048
        angularVelocity 0.40151623110152646 5.851735474727707e-16 4.514624137449195e-15
      }
    }
  ]
  name "robot2"
  boundingObject USE boxA
  physics Physics {
    mass 0.28
  }
  controller "JointController"
  linearVelocity -1.8954862473119117e-15 0.31185479516938863 -0.03994295978888038
  angularVelocity 0.0396103804699673 -2.4617059093821398e-16 6.925850736018836e-15
}
DEF robot1 Robot {
  translation -3.714212522294727e-16 0.1676924498733246 0.9858180832242291
  rotation 0.9999999999999999 2.5419020167470995e-16 3.3685343468554522e-18 1.5043081068111115
  children [
    DEF connector1 Connector {
      translation 0 -0.42 0
      rotation 0 0 1 3.14159
    }
    DEF connector2 Connector {
      translation 0.365 0.42 0
      rotation 0 0 1 -1.5708
      name "connector2"
    }
    DEF connector3 Connector {
      translation -0.365 0.42 0
      rotation 0 0 1 1.5708
      name "connector3"
    }
    Receiver {
      channel 1
    }
    Emitter {
      channel 1
    }
    DEF gyro Gyro {
    }
    DEF accelerometer Accelerometer {
    }
    DEF leg1 Shape {
      appearance PBRAppearance {
        baseColor 0.45098 0.823529 0.0862745
        metalness 0
      }
      geometry DEF boxA Box {
        size 0.73 0.84 0.3
      }
    }
    HingeJoint {
      jointParameters HingeJointParameters {
        position 0.055430930239543125
        anchor 0 0.42 0
        staticFriction 0.1
      }
      device [
        RotationalMotor {
          name "motor"
        }
      ]
      endPoint Solid {
        translation 0 0.6995699478075428 0.015512713588790198
        rotation 1 -2.9579488415658164e-15 5.621355861672541e-17 0.055430930239543125
        children [
          DEF connector4 Connector {
            translation 0 0.434 0
            isLocked TRUE
            autoLock TRUE
            distanceTolerance 0.1
            axisTolerance 3.14
            rotationTolerance 3.14
            snap FALSE
          }
          DEF leg2 Shape {
            appearance PBRAppearance {
              baseColor 0.45098 0.823529 0.0862745
              metalness 0
            }
            geometry DEF boxB Box {
              size 0.73 0.868 0.3
            }
          }
        ]
        boundingObject USE boxB
        physics Physics {
          mass 0.4
        }
        linearVelocity -2.0104916985137262e-15 0.34579009689711904 -0.0374689642273696
        angularVelocity 0.039704002829487314 4.3710984841338215e-16 5.653894349349305e-15
      }
    }
  ]
  name "robot1"
  boundingObject USE boxA
  physics Physics {
    mass 0.28
  }
  controller "JointController"
  linearVelocity -1.9083410447049956e-15 0.35346974460500796 0.0008830599835725206
  angularVelocity -0.03011010512317336 2.878951848700182e-16 8.664038154054119e-15
}
